{
  "comments": [
    {
      "key": {
        "uuid": "bab921fb_85eff3af",
        "filename": "ci-scripts/dlrnapi_promoter/test_get_latest_hashes.py",
        "patchSetId": 3
      },
      "lineNbr": 73,
      "author": {
        "id": 84
      },
      "writtenOn": "2018-06-12T16:38:34Z",
      "side": 1,
      "message": "This test is not working.",
      "range": {
        "startLine": 46,
        "startChar": 0,
        "endLine": 73,
        "endChar": 47
      },
      "revId": "106e9a0cd07e602ce0577ef0a4653774376bc2a1",
      "serverId": "270e2033-b340-4cff-9539-693957ebf0e7",
      "unresolved": false
    },
    {
      "key": {
        "uuid": "bab921fb_a5f2f798",
        "filename": "tox.ini",
        "patchSetId": 3
      },
      "lineNbr": 23,
      "author": {
        "id": 84
      },
      "writtenOn": "2018-06-12T16:38:34Z",
      "side": 1,
      "message": "The dlrnapi_promoter script looks like it is not py3 compatible. I get an error in py3 when importing get_latest_hashes related to the \"from sets import Set\"",
      "range": {
        "startLine": 20,
        "startChar": 0,
        "endLine": 23,
        "endChar": 35
      },
      "revId": "106e9a0cd07e602ce0577ef0a4653774376bc2a1",
      "serverId": "270e2033-b340-4cff-9539-693957ebf0e7",
      "unresolved": false
    }
  ]
}